Workbook

Sheet Complaint Data
A1: Complaint_ID | B1: Date_Received | C1: Company | D1: State | E1: Issue | F1: Submitted_Via | G1: Response | H1: Days_to_Close | I1: Amount_Relief
A2: CC0001 | B2: 45823 | C2: Prime Card | D2: Delhi | E2: Billing dispute | F2: Web | G2: In progress | I2: 0
A3: CC0002 | B3: 45932 | C3: ABC Bank | D3: Maharashtra | E3: Identity theft | F3: Web | G3: Closed with explanation | H3: 19 | I3: 0
A4: CC0003 | B4: 45702 | C4: XYZ Bank | D4: Tamil Nadu | E4: Customer service | F4: Postal mail | G4: Closed with explanation | H4: 3 | I4: 0
A5: CC0004 | B5: 45688 | C5: XYZ Bank | D5: Delhi | E5: Closing account | F5: Email | G5: Closed without relief | H5: 4 | I5: 0
A6: CC0005 | B6: 45689 | C6: XYZ Bank | D6: Tamil Nadu | E6: Customer service | F6: Referral | G6: Closed with monetary relief | H6: 13 | I6: 456
A7: CC0006 | B7: 45806 | C7: ABC Bank | D7: Maharashtra | E7: Late fee | F7: Email | G7: Closed with explanation | H7: 18 | I7: 0
A8: CC0007 | B8: 46007 | C8: Global Finance | D8: Delhi | E8: Identity theft | F8: Phone | G8: Closed with explanation | H8: 19 | I8: 0
A9: CC0008 | B9: 45707 | C9: ABC Bank | D9: Maharashtra | E9: Identity theft | F9: Postal mail | G9: Closed with monetary relief | H9: 3 | I9: 4673
A10: CC0009 | B10: 46006 | C10: Global Finance | D10: Telangana | E10: Late fee | F10: Phone | G10: Closed with monetary relief | H10: 11 | I10: 3864
A11: CC0010 | B11: 45785 | C11: ABC Bank | D11: Maharashtra | E11: Late fee | F11: Email | G11: Closed without relief | H11: 8 | I11: 0
A12: CC0011 | B12: 45911 | C12: National Bank | D12: Maharashtra | E12: Billing dispute | F12: Web | G12: Closed without relief | H12: 15 | I12: 0
A13: CC0012 | B13: 45920 | C13: XYZ Bank | D13: Telangana | E13: APR or interest rate | F13: Web | G13: Closed with explanation | H13: 11 | I13: 0
A14: CC0013 | B14: 46000 | C14: Global Finance | D14: Gujarat | E14: Credit determination | F14: Phone | G14: Closed with explanation | H14: 18 | I14: 0
... A37: CC0036 | B37: 45780 | C37: XYZ Bank | D37: Maharashtra | E37: APR or interest rate | F37: Phone | G37: Closed without relief | H37: 8 | I37: 0
A38: CC0037 | B38: 45672 | C38: National Bank | D38: Telangana | E38: Late fee | F38: Referral | G38: In progress | I38: 0
A39: CC0038 | B39: 46012 | C39: National Bank | D39: Karnataka | E39: Billing dispute | F39: Referral | G39: Closed with monetary relief | H39: 12 | I39: 3713
A40: CC0039 | B40: 45710 | C40: National Bank | D40: Kerala | E40: APR or interest rate | F40: Email | G40: Closed with explanation | H40: 7 | I40: 0
A41: CC0040 | B41: 45970 | C41: National Bank | D41: Gujarat | E41: Closing account | F41: Web | G41: Closed without relief | H41: 16 | I41: 0
A42: CC0041 | B42: 45996 | C42: XYZ Bank | D42: Telangana | E42: Identity theft | F42: Postal mail | G42: Closed with explanation | H42: 13 | I42: 0
A43: CC0042 | B43: 45983 | C43: Prime Card | D43: Telangana | E43: Closing account | F43: Web | G43: Closed with explanation | H43: 13 | I43: 0
A44: CC0043 | B44: 45739 | C44: ABC Bank | D44: Kerala | E44: Customer service | F44: Postal mail | G44: Closed with explanation | H44: 5 | I44: 0
A45: CC0044 | B45: 45993 | C45: Prime Card | D45: Delhi | E45: Late fee | F45: Referral | G45: Closed with explanation | H45: 20 | I45: 0
A46: CC0045 | B46: 45938 | C46: ABC Bank | D46: Maharashtra | E46: Closing account | F46: Referral | G46: Closed with monetary relief | H46: 1 | I46: 166
A47: CC0046 | B47: 45880 | C47: XYZ Bank | D47: Gujarat | E47: Credit determination | F47: Referral | G47: In progress | I47: 0
A48: CC0047 | B48: 45672 | C48: Global Finance | D48: Kerala | E48: Credit determination | F48: Email | G48: Closed with explanation | H48: 10 | I48: 0
A49: CC0048 | B49: 45824 | C49: XYZ Bank | D49: Tamil Nadu | E49: Closing account | F49: Phone | G49: Closed with explanation | H49: 14 | I49: 0
A50: CC0049 | B50: 45892 | C50: Prime Card | D50: Gujarat | E50: Customer service | F50: Referral | G50: Closed with non-monetary relief | H50: 17 | I50: 0
A51: CC0050 | B51: 45930 | C51: ABC Bank | D51: Gujarat | E51: APR or interest rate | F51: Referral | G51: Closed with explanation | H51: 17 | I51: 0
A52: CC0051 | B52: 45969 | C52: XYZ Bank | D52: Kerala | E52: APR or interest rate | F52: Email | G52: Closed with explanation | H52: 5 | I52: 0
A53: CC0052 | B53: 45719 | C53: Global Finance | D53: Maharashtra | E53: APR or interest rate | F53: Web | G53: Closed with monetary relief | H53: 11 | I53: 4296
A54: CC0053 | B54: 45944 | C54: National Bank | D54: Tamil Nadu | E54: Credit determination | F54: Web | G54: Closed with explanation | H54: 7 | I54: 0
A55: CC0054 | B55: 45917 | C55: Prime Card | D55: Karnataka | E55: Customer service | F55: Email | G55: Closed with monetary relief | H55: 1 | I55: 569
A56: CC0055 | B56: 45968 | C56: Global Finance | D56: Maharashtra | E56: Credit determination | F56: Postal mail | G56: Closed with monetary relief | H56: 9 | I56: 3755
A57: CC0056 | B57: 45917 | C57: Global Finance | D57: Karnataka | E57: Customer service | F57: Referral | G57: In progress | I57: 0
A58: CC0057 | B58: 45887 | C58: Prime Card | D58: Telangana | E58: Late fee | F58: Web | G58: Closed with explanation | H58: 4 | I58: 0
A59: CC0058 | B59: 46001 | C59: XYZ Bank | D59: Delhi | E59: Late fee | F59: Web | G59: Closed with explanation | H59: 3 | I59: 0
A60: CC0059 | B60: 45737 | C60: National Bank | D60: Kerala | E60: Late fee | F60: Referral | G60: In progress | I60: 0
A61: CC0060 | B61: 45897 | C61: Prime Card | D61: Telangana | E61: Identity theft | F61: Referral | G61: Closed with explanation | H61: 4 | I61: 0
A62: CC0061 | B62: 45740 | C62: Prime Card | D62: Karnataka | E62: APR or interest rate | F62: Referral | G62: Closed with non-monetary relief | H62: 17 | I62: 0
...

Sheet Dashboard
A1: CREDIT CARD COMPLAINTS DASHBOARD
A3: TOTAL COMPLAINTS | D3: CLOSED COMPLAINTS % | G3: IN PROGRESS
A5: =COUNTA('Complaint Data'!A2:A501) | D5: =COUNTIF('Complaint Data'!G2:G501,"<>In progress")/COUNTA('Complaint Data'!A2:A501) | G5: =COUNTIF('Complaint Data'!G2:G501,"In progress")
A8: Complaints by Issue | F8: Complaints by Company
A9: Issue | B9: Complaints | F9: Company | G9: Complaints
A10: Billing dispute | B10: =COUNTIF('Complaint Data'!E:E,A10) | F10: ABC Bank | G10: =COUNTIF('Complaint Data'!C:C,F10)
A11: Identity theft | B11: =COUNTIF('Complaint Data'!E:E,A11) | F11: XYZ Bank | G11: =COUNTIF('Complaint Data'!C:C,F11)
A12: Late fee | B12: =COUNTIF('Complaint Data'!E:E,A12) | F12: National Bank | G12: =COUNTIF('Complaint Data'!C:C,F12)
A13: APR or interest rate | B13: =COUNTIF('Complaint Data'!E:E,A13) | F13: Prime Card | G13: =COUNTIF('Complaint Data'!C:C,F13)
A14: Customer service | B14: =COUNTIF('Complaint Data'!E:E,A14) | F14: Global Finance | G14: =COUNTIF('Complaint Data'!C:C,F14)
A15: Closing account | B15: =COUNTIF('Complaint Data'!E:E,A15)
A16: Credit determination | B16: =COUNTIF('Complaint Data'!E:E,A16)
A24: Monthly Complaint Trend
A25: Month | B25: Complaints
A26: 45658 | B26: =COUNTIFS('Complaint Data'!B:B,">="&A26,'Complaint Data'!B:B,"<"&EDATE(A26,1))
A27: 45689 | B27: =COUNTIFS('Complaint Data'!B:B,">="&A27,'Complaint Data'!B:B,"<"&EDATE(A27,1))
A28: 45717 | B28: =COUNTIFS('Complaint Data'!B:B,">="&A28,'Complaint Data'!B:B,"<"&EDATE(A28,1))
A29: 45748 | B29: =COUNTIFS('Complaint Data'!B:B,">="&A29,'Complaint Data'!B:B,"<"&EDATE(A29,1))
A30: 45778 | B30: =COUNTIFS('Complaint Data'!B:B,">="&A30,'Complaint Data'!B:B,"<"&EDATE(A30,1))
A31: 45809 | B31: =COUNTIFS('Complaint Data'!B:B,">="&A31,'Complaint Data'!B:B,"<"&EDATE(A31,1))
A32: 45839 | B32: =COUNTIFS('Complaint Data'!B:B,">="&A32,'Complaint Data'!B:B,"<"&EDATE(A32,1))
A33: 45870 | B33: =COUNTIFS('Complaint Data'!B:B,">="&A33,'Complaint Data'!B:B,"<"&EDATE(A33,1))
A34: 45901 | B34: =COUNTIFS('Complaint Data'!B:B,">="&A34,'Complaint Data'!B:B,"<"&EDATE(A34,1))
A35: 45931 | B35: =COUNTIFS('Complaint Data'!B:B,">="&A35,'Complaint Data'!B:B,"<"&EDATE(A35,1))
A36: 45962 | B36: =COUNTIFS('Complaint Data'!B:B,">="&A36,'Complaint Data'!B:B,"<"&EDATE(A36,1))
A37: 45992 | B37: =COUNTIFS('Complaint Data'!B:B,">="&A37,'Complaint Data'!B:B,"<"&EDATE(A37,1))

Sheet How to Build
A1: How to customize this dashboard
A3: 1. Replace the sample rows in 'Complaint Data' with your real Excel data.
A4: 2. Keep the same column names, or update the formulas in the Dashboard.
A5: 3. The 3 main KPIs are: Total Complaints, Closed Complaints %, and In Progress.
A6: 4. Use the Dashboard charts to explain issue-wise, company-wise, and monthly trends.
A7: 5. For a more advanced version, add PivotTables + Slicers for Year, Company and State.
